[2024-09-21T06:21:09.976+0000] {local_task_job_runner.py:120} INFO - ::group::Pre task execution logs
[2024-09-21T06:21:10.000+0000] {taskinstance.py:2076} INFO - Dependencies all met for dep_context=non-requeueable deps ti=<TaskInstance: NYC_Taxi_pipeline.dbt_run_test2 scheduled__2024-09-20T00:00:00+00:00 [queued]>
[2024-09-21T06:21:10.010+0000] {taskinstance.py:2076} INFO - Dependencies all met for dep_context=requeueable deps ti=<TaskInstance: NYC_Taxi_pipeline.dbt_run_test2 scheduled__2024-09-20T00:00:00+00:00 [queued]>
[2024-09-21T06:21:10.011+0000] {taskinstance.py:2306} INFO - Starting attempt 1 of 1
[2024-09-21T06:21:10.055+0000] {taskinstance.py:2330} INFO - Executing <Task(BashOperator): dbt_run_test2> on 2024-09-20 00:00:00+00:00
[2024-09-21T06:21:10.062+0000] {standard_task_runner.py:63} INFO - Started process 59 to run task
[2024-09-21T06:21:10.064+0000] {standard_task_runner.py:90} INFO - Running: ['***', 'tasks', 'run', 'NYC_Taxi_pipeline', 'dbt_run_test2', 'scheduled__2024-09-20T00:00:00+00:00', '--job-id', '27', '--raw', '--subdir', 'DAGS_FOLDER/NYC_Taxi_pipeline.py', '--cfg-path', '/tmp/tmph1gwh1tv']
[2024-09-21T06:21:10.067+0000] {standard_task_runner.py:91} INFO - Job 27: Subtask dbt_run_test2
[2024-09-21T06:21:10.159+0000] {task_command.py:426} INFO - Running <TaskInstance: NYC_Taxi_pipeline.dbt_run_test2 scheduled__2024-09-20T00:00:00+00:00 [running]> on host a7d215ebb90a
[2024-09-21T06:21:10.311+0000] {taskinstance.py:2648} INFO - Exporting env vars: AIRFLOW_CTX_DAG_OWNER='Mahmoud' AIRFLOW_CTX_DAG_ID='NYC_Taxi_pipeline' AIRFLOW_CTX_TASK_ID='dbt_run_test2' AIRFLOW_CTX_EXECUTION_DATE='2024-09-20T00:00:00+00:00' AIRFLOW_CTX_TRY_NUMBER='1' AIRFLOW_CTX_DAG_RUN_ID='scheduled__2024-09-20T00:00:00+00:00'
[2024-09-21T06:21:10.312+0000] {taskinstance.py:430} INFO - ::endgroup::
[2024-09-21T06:21:10.322+0000] {subprocess.py:63} INFO - Tmp dir root location: /tmp
[2024-09-21T06:21:10.322+0000] {subprocess.py:75} INFO - Running command: ['/bin/bash', '-c', 'dbt run --profiles-dir /opt/***/DBT_Project --project-dir /opt/***/dbt_trip --models test2']
[2024-09-21T06:21:10.335+0000] {subprocess.py:86} INFO - Output:
[2024-09-21T06:21:14.435+0000] {subprocess.py:93} INFO - [0m06:21:14  Running with dbt=1.8.6
[2024-09-21T06:21:14.743+0000] {subprocess.py:93} INFO - [0m06:21:14  Registered adapter: postgres=1.8.2
[2024-09-21T06:21:14.927+0000] {subprocess.py:93} INFO - [0m06:21:14  Unable to do partial parsing because of a version mismatch
[2024-09-21T06:21:16.730+0000] {subprocess.py:93} INFO - [0m06:21:16  [[33mWARNING[0m]: Configuration paths exist in your dbt_project.yml file which do not apply to any resources.
[2024-09-21T06:21:16.731+0000] {subprocess.py:93} INFO - There are 2 unused configuration paths:
[2024-09-21T06:21:16.731+0000] {subprocess.py:93} INFO - - models.fact_trip.staging
[2024-09-21T06:21:16.731+0000] {subprocess.py:93} INFO - - models.fact_trip.core
[2024-09-21T06:21:17.362+0000] {subprocess.py:93} INFO - [0m06:21:17  Found 2 models, 1 seed, 1 source, 423 macros
[2024-09-21T06:21:17.364+0000] {subprocess.py:93} INFO - [0m06:21:17
[2024-09-21T06:21:17.519+0000] {subprocess.py:93} INFO - [0m06:21:17
[2024-09-21T06:21:17.520+0000] {subprocess.py:93} INFO - [0m06:21:17  Finished running  in 0 hours 0 minutes and 0.15 seconds (0.15s).
[2024-09-21T06:21:17.520+0000] {subprocess.py:93} INFO - [0m06:21:17  Encountered an error:
[2024-09-21T06:21:17.521+0000] {subprocess.py:93} INFO - Database Error
[2024-09-21T06:21:17.521+0000] {subprocess.py:93} INFO -   connection to server at "172.20.0.3", port 5432 failed: Connection refused
[2024-09-21T06:21:17.521+0000] {subprocess.py:93} INFO -   	Is the server running on that host and accepting TCP/IP connections?
[2024-09-21T06:21:17.521+0000] {subprocess.py:93} INFO - 
[2024-09-21T06:21:18.589+0000] {subprocess.py:97} INFO - Command exited with return code 2
[2024-09-21T06:21:18.590+0000] {taskinstance.py:441} INFO - ::group::Post task execution logs
[2024-09-21T06:21:18.602+0000] {taskinstance.py:2905} ERROR - Task failed with exception
Traceback (most recent call last):
  File "/home/airflow/.local/lib/python3.9/site-packages/airflow/models/taskinstance.py", line 465, in _execute_task
    result = _execute_callable(context=context, **execute_callable_kwargs)
  File "/home/airflow/.local/lib/python3.9/site-packages/airflow/models/taskinstance.py", line 432, in _execute_callable
    return execute_callable(context=context, **execute_callable_kwargs)
  File "/home/airflow/.local/lib/python3.9/site-packages/airflow/models/baseoperator.py", line 400, in wrapper
    return func(self, *args, **kwargs)
  File "/home/airflow/.local/lib/python3.9/site-packages/airflow/operators/bash.py", line 243, in execute
    raise AirflowException(
airflow.exceptions.AirflowException: Bash command failed. The command returned a non-zero exit code 2.
[2024-09-21T06:21:18.612+0000] {taskinstance.py:1206} INFO - Marking task as FAILED. dag_id=NYC_Taxi_pipeline, task_id=dbt_run_test2, run_id=scheduled__2024-09-20T00:00:00+00:00, execution_date=20240920T000000, start_date=20240921T062110, end_date=20240921T062118
[2024-09-21T06:21:18.681+0000] {standard_task_runner.py:110} ERROR - Failed to execute job 27 for task dbt_run_test2 (Bash command failed. The command returned a non-zero exit code 2.; 59)
[2024-09-21T06:21:18.726+0000] {local_task_job_runner.py:240} INFO - Task exited with return code 1
[2024-09-21T06:21:18.736+0000] {local_task_job_runner.py:222} INFO - ::endgroup::
