[2024-09-28T05:43:58.814+0000] {local_task_job_runner.py:120} INFO - ::group::Pre task execution logs
[2024-09-28T05:43:58.837+0000] {taskinstance.py:2076} INFO - Dependencies all met for dep_context=non-requeueable deps ti=<TaskInstance: Taxi_trip_pipeline.mark_files_as_processed scheduled__2024-09-27T00:00:00+00:00 [queued]>
[2024-09-28T05:43:58.847+0000] {taskinstance.py:2076} INFO - Dependencies all met for dep_context=requeueable deps ti=<TaskInstance: Taxi_trip_pipeline.mark_files_as_processed scheduled__2024-09-27T00:00:00+00:00 [queued]>
[2024-09-28T05:43:58.847+0000] {taskinstance.py:2306} INFO - Starting attempt 1 of 1
[2024-09-28T05:43:58.858+0000] {taskinstance.py:2330} INFO - Executing <Task(PythonOperator): mark_files_as_processed> on 2024-09-27 00:00:00+00:00
[2024-09-28T05:43:58.865+0000] {standard_task_runner.py:63} INFO - Started process 134 to run task
[2024-09-28T05:43:58.867+0000] {standard_task_runner.py:90} INFO - Running: ['***', 'tasks', 'run', 'Taxi_trip_pipeline', 'mark_files_as_processed', 'scheduled__2024-09-27T00:00:00+00:00', '--job-id', '225', '--raw', '--subdir', 'DAGS_FOLDER/taxi_trip.py', '--cfg-path', '/tmp/tmpel6_paw_']
[2024-09-28T05:43:58.869+0000] {standard_task_runner.py:91} INFO - Job 225: Subtask mark_files_as_processed
[2024-09-28T05:43:58.909+0000] {task_command.py:426} INFO - Running <TaskInstance: Taxi_trip_pipeline.mark_files_as_processed scheduled__2024-09-27T00:00:00+00:00 [running]> on host d7ea763741e5
[2024-09-28T05:43:58.984+0000] {taskinstance.py:2648} INFO - Exporting env vars: AIRFLOW_CTX_DAG_OWNER='Mahmoud' AIRFLOW_CTX_DAG_ID='Taxi_trip_pipeline' AIRFLOW_CTX_TASK_ID='mark_files_as_processed' AIRFLOW_CTX_EXECUTION_DATE='2024-09-27T00:00:00+00:00' AIRFLOW_CTX_TRY_NUMBER='1' AIRFLOW_CTX_DAG_RUN_ID='scheduled__2024-09-27T00:00:00+00:00'
[2024-09-28T05:43:58.985+0000] {taskinstance.py:430} INFO - ::endgroup::
[2024-09-28T05:43:58.996+0000] {db_utils.py:19} ERROR - Error while connecting to PostgreSQL: (psycopg2.OperationalError) connection to server at "172.20.0.3", port 5432 failed: Connection refused
	Is the server running on that host and accepting TCP/IP connections?

(Background on this error at: https://sqlalche.me/e/14/e3q8)
[2024-09-28T05:43:59.012+0000] {taxi_trip.py:108} INFO - All files marked as processed successfully.
[2024-09-28T05:43:59.012+0000] {python.py:237} INFO - Done. Returned value was: None
[2024-09-28T05:43:59.012+0000] {taskinstance.py:441} INFO - ::group::Post task execution logs
[2024-09-28T05:43:59.020+0000] {taskinstance.py:1206} INFO - Marking task as SUCCESS. dag_id=Taxi_trip_pipeline, task_id=mark_files_as_processed, run_id=scheduled__2024-09-27T00:00:00+00:00, execution_date=20240927T000000, start_date=20240928T054358, end_date=20240928T054359
[2024-09-28T05:43:59.039+0000] {local_task_job_runner.py:240} INFO - Task exited with return code 0
[2024-09-28T05:43:59.054+0000] {taskinstance.py:3498} INFO - 0 downstream tasks scheduled from follow-on schedule check
[2024-09-28T05:43:59.055+0000] {local_task_job_runner.py:222} INFO - ::endgroup::
