[2024-10-01T14:28:04.580+0000] {local_task_job_runner.py:120} INFO - ::group::Pre task execution logs
[2024-10-01T14:28:04.608+0000] {taskinstance.py:2076} INFO - Dependencies all met for dep_context=non-requeueable deps ti=<TaskInstance: Taxi_trip_pipeline.dbt_run_fact_trip manual__2024-10-01T13:50:22.623616+00:00 [queued]>
[2024-10-01T14:28:04.618+0000] {taskinstance.py:2076} INFO - Dependencies all met for dep_context=requeueable deps ti=<TaskInstance: Taxi_trip_pipeline.dbt_run_fact_trip manual__2024-10-01T13:50:22.623616+00:00 [queued]>
[2024-10-01T14:28:04.619+0000] {taskinstance.py:2306} INFO - Starting attempt 2 of 2
[2024-10-01T14:28:04.632+0000] {taskinstance.py:2330} INFO - Executing <Task(BashOperator): dbt_run_fact_trip> on 2024-10-01 13:50:22.623616+00:00
[2024-10-01T14:28:04.641+0000] {standard_task_runner.py:63} INFO - Started process 1687 to run task
[2024-10-01T14:28:04.643+0000] {standard_task_runner.py:90} INFO - Running: ['***', 'tasks', 'run', 'Taxi_trip_pipeline', 'dbt_run_fact_trip', 'manual__2024-10-01T13:50:22.623616+00:00', '--job-id', '257', '--raw', '--subdir', 'DAGS_FOLDER/taxi_trip.py', '--cfg-path', '/tmp/tmp_h6xu3u7']
[2024-10-01T14:28:04.645+0000] {standard_task_runner.py:91} INFO - Job 257: Subtask dbt_run_fact_trip
[2024-10-01T14:28:04.690+0000] {task_command.py:426} INFO - Running <TaskInstance: Taxi_trip_pipeline.dbt_run_fact_trip manual__2024-10-01T13:50:22.623616+00:00 [running]> on host fcb0f9e87e2b
[2024-10-01T14:28:04.779+0000] {taskinstance.py:2648} INFO - Exporting env vars: AIRFLOW_CTX_DAG_OWNER='Mahmoud' AIRFLOW_CTX_DAG_ID='Taxi_trip_pipeline' AIRFLOW_CTX_TASK_ID='dbt_run_fact_trip' AIRFLOW_CTX_EXECUTION_DATE='2024-10-01T13:50:22.623616+00:00' AIRFLOW_CTX_TRY_NUMBER='2' AIRFLOW_CTX_DAG_RUN_ID='manual__2024-10-01T13:50:22.623616+00:00'
[2024-10-01T14:28:04.780+0000] {taskinstance.py:430} INFO - ::endgroup::
[2024-10-01T14:28:04.791+0000] {subprocess.py:63} INFO - Tmp dir root location: /tmp
[2024-10-01T14:28:04.791+0000] {subprocess.py:75} INFO - Running command: ['/usr/bin/bash', '-c', 'dbt run --profiles-dir /opt/***/DBT_Project  --project-dir /opt/***/dbt_trip --models Fact_trips']
[2024-10-01T14:28:04.805+0000] {subprocess.py:86} INFO - Output:
[2024-10-01T14:28:07.289+0000] {subprocess.py:93} INFO - [0m14:28:07  Running with dbt=1.8.0
[2024-10-01T14:28:07.593+0000] {subprocess.py:93} INFO - [0m14:28:07  Registered adapter: postgres=1.8.0
[2024-10-01T14:28:08.215+0000] {subprocess.py:93} INFO - [0m14:28:08  [[33mWARNING[0m]: Found patch for macro "payment_type_mapping" which was not found
[2024-10-01T14:28:08.217+0000] {subprocess.py:93} INFO - [0m14:28:08  [[33mWARNING[0m]: Found patch for macro "rate_code_mapping" which was not found
[2024-10-01T14:28:08.218+0000] {subprocess.py:93} INFO - [0m14:28:08  [[33mWARNING[0m]: Found patch for macro "store_and_fwd_flag_mapping" which was not found
[2024-10-01T14:28:08.219+0000] {subprocess.py:93} INFO - [0m14:28:08  [[33mWARNING[0m]: Found patch for macro "trip_type_mapping" which was not found
[2024-10-01T14:28:08.221+0000] {subprocess.py:93} INFO - [0m14:28:08  [[33mWARNING[0m]: Found patch for macro "vendor_mapping" which was not found
[2024-10-01T14:28:08.309+0000] {subprocess.py:93} INFO - [0m14:28:08  [[33mWARNING[0m]: Deprecated functionality
[2024-10-01T14:28:08.309+0000] {subprocess.py:93} INFO - The `tests` config has been renamed to `data_tests`. Please see
[2024-10-01T14:28:08.310+0000] {subprocess.py:93} INFO - https://docs.getdbt.com/docs/build/data-tests#new-data_tests-syntax for more
[2024-10-01T14:28:08.310+0000] {subprocess.py:93} INFO - information.
[2024-10-01T14:28:08.536+0000] {subprocess.py:93} INFO - [0m14:28:08  [[33mWARNING[0m]: Configuration paths exist in your dbt_project.yml file which do not apply to any resources.
[2024-10-01T14:28:08.537+0000] {subprocess.py:93} INFO - There are 2 unused configuration paths:
[2024-10-01T14:28:08.537+0000] {subprocess.py:93} INFO - - models.fact_trip.Dimensions
[2024-10-01T14:28:08.537+0000] {subprocess.py:93} INFO - - models.fact_trip.staging
[2024-10-01T14:28:08.719+0000] {subprocess.py:93} INFO - [0m14:28:08  Found 4 models, 6 data tests, 3 sources, 566 macros
[2024-10-01T14:28:08.722+0000] {subprocess.py:93} INFO - [0m14:28:08
[2024-10-01T14:28:08.846+0000] {subprocess.py:93} INFO - [0m14:28:08  Concurrency: 3 threads (target='dev')
[2024-10-01T14:28:08.847+0000] {subprocess.py:93} INFO - [0m14:28:08
[2024-10-01T14:28:08.857+0000] {subprocess.py:93} INFO - [0m14:28:08  1 of 1 START sql view model analysis.Fact_trips ................................ [RUN]
[2024-10-01T14:28:08.941+0000] {subprocess.py:93} INFO - [0m14:28:08  1 of 1 ERROR creating sql view model analysis.Fact_trips ....................... [[31mERROR[0m in 0.08s]
[2024-10-01T14:28:08.952+0000] {subprocess.py:93} INFO - [0m14:28:08
[2024-10-01T14:28:08.953+0000] {subprocess.py:93} INFO - [0m14:28:08  Finished running 1 view model in 0 hours 0 minutes and 0.23 seconds (0.23s).
[2024-10-01T14:28:09.003+0000] {subprocess.py:93} INFO - [0m14:28:09
[2024-10-01T14:28:09.004+0000] {subprocess.py:93} INFO - [0m14:28:09  [31mCompleted with 1 error and 0 warnings:[0m
[2024-10-01T14:28:09.004+0000] {subprocess.py:93} INFO - [0m14:28:09
[2024-10-01T14:28:09.005+0000] {subprocess.py:93} INFO - [0m14:28:09    Database Error in model Fact_trips (models/Fact/Fact_trips.sql)
[2024-10-01T14:28:09.005+0000] {subprocess.py:93} INFO -   column "VendorID" does not exist
[2024-10-01T14:28:09.006+0000] {subprocess.py:93} INFO -   LINE 28:         ROW_NUMBER() OVER (ORDER BY "VendorID", "pickup_date...
[2024-10-01T14:28:09.006+0000] {subprocess.py:93} INFO -                                                ^
[2024-10-01T14:28:09.006+0000] {subprocess.py:93} INFO -   HINT:  Perhaps you meant to reference the column "t.vendorid".
[2024-10-01T14:28:09.006+0000] {subprocess.py:93} INFO -   compiled code at target/run/fact_trip/models/Fact/Fact_trips.sql
[2024-10-01T14:28:09.006+0000] {subprocess.py:93} INFO - [0m14:28:09
[2024-10-01T14:28:09.007+0000] {subprocess.py:93} INFO - [0m14:28:09  Done. PASS=0 WARN=0 ERROR=1 SKIP=0 TOTAL=1
[2024-10-01T14:28:10.103+0000] {subprocess.py:97} INFO - Command exited with return code 1
[2024-10-01T14:28:10.104+0000] {taskinstance.py:441} INFO - ::group::Post task execution logs
[2024-10-01T14:28:10.114+0000] {taskinstance.py:2905} ERROR - Task failed with exception
Traceback (most recent call last):
  File "/home/airflow/.local/lib/python3.9/site-packages/airflow/models/taskinstance.py", line 465, in _execute_task
    result = _execute_callable(context=context, **execute_callable_kwargs)
  File "/home/airflow/.local/lib/python3.9/site-packages/airflow/models/taskinstance.py", line 432, in _execute_callable
    return execute_callable(context=context, **execute_callable_kwargs)
  File "/home/airflow/.local/lib/python3.9/site-packages/airflow/models/baseoperator.py", line 400, in wrapper
    return func(self, *args, **kwargs)
  File "/home/airflow/.local/lib/python3.9/site-packages/airflow/operators/bash.py", line 243, in execute
    raise AirflowException(
airflow.exceptions.AirflowException: Bash command failed. The command returned a non-zero exit code 1.
[2024-10-01T14:28:10.119+0000] {taskinstance.py:1206} INFO - Marking task as FAILED. dag_id=Taxi_trip_pipeline, task_id=dbt_run_fact_trip, run_id=manual__2024-10-01T13:50:22.623616+00:00, execution_date=20241001T135022, start_date=20241001T142804, end_date=20241001T142810
[2024-10-01T14:28:10.133+0000] {standard_task_runner.py:110} ERROR - Failed to execute job 257 for task dbt_run_fact_trip (Bash command failed. The command returned a non-zero exit code 1.; 1687)
[2024-10-01T14:28:10.148+0000] {local_task_job_runner.py:240} INFO - Task exited with return code 1
[2024-10-01T14:28:10.165+0000] {taskinstance.py:3498} INFO - 0 downstream tasks scheduled from follow-on schedule check
[2024-10-01T14:28:10.166+0000] {local_task_job_runner.py:222} INFO - ::endgroup::
