[2024-09-21T09:18:31.476+0000] {local_task_job_runner.py:120} INFO - ::group::Pre task execution logs
[2024-09-21T09:18:31.510+0000] {taskinstance.py:2076} INFO - Dependencies all met for dep_context=non-requeueable deps ti=<TaskInstance: NYC_Taxi_pipeline.dbt_models.dbt_Model_STG_dim_Location manual__2024-09-21T09:11:40.867116+00:00 [queued]>
[2024-09-21T09:18:31.526+0000] {taskinstance.py:2076} INFO - Dependencies all met for dep_context=requeueable deps ti=<TaskInstance: NYC_Taxi_pipeline.dbt_models.dbt_Model_STG_dim_Location manual__2024-09-21T09:11:40.867116+00:00 [queued]>
[2024-09-21T09:18:31.526+0000] {taskinstance.py:2306} INFO - Starting attempt 3 of 3
[2024-09-21T09:18:31.550+0000] {taskinstance.py:2330} INFO - Executing <Task(BashOperator): dbt_models.dbt_Model_STG_dim_Location> on 2024-09-21 09:11:40.867116+00:00
[2024-09-21T09:18:31.563+0000] {standard_task_runner.py:63} INFO - Started process 356 to run task
[2024-09-21T09:18:31.567+0000] {standard_task_runner.py:90} INFO - Running: ['***', 'tasks', 'run', 'NYC_Taxi_pipeline', 'dbt_models.dbt_Model_STG_dim_Location', 'manual__2024-09-21T09:11:40.867116+00:00', '--job-id', '42', '--raw', '--subdir', 'DAGS_FOLDER/NYC_Taxi_pipeline.py', '--cfg-path', '/tmp/tmpb90a_w3i']
[2024-09-21T09:18:31.571+0000] {standard_task_runner.py:91} INFO - Job 42: Subtask dbt_models.dbt_Model_STG_dim_Location
[2024-09-21T09:18:31.645+0000] {task_command.py:426} INFO - Running <TaskInstance: NYC_Taxi_pipeline.dbt_models.dbt_Model_STG_dim_Location manual__2024-09-21T09:11:40.867116+00:00 [running]> on host a7d215ebb90a
[2024-09-21T09:18:31.764+0000] {taskinstance.py:2648} INFO - Exporting env vars: AIRFLOW_CTX_DAG_OWNER='***' AIRFLOW_CTX_DAG_ID='NYC_Taxi_pipeline' AIRFLOW_CTX_TASK_ID='dbt_models.dbt_Model_STG_dim_Location' AIRFLOW_CTX_EXECUTION_DATE='2024-09-21T09:11:40.867116+00:00' AIRFLOW_CTX_TRY_NUMBER='3' AIRFLOW_CTX_DAG_RUN_ID='manual__2024-09-21T09:11:40.867116+00:00'
[2024-09-21T09:18:31.766+0000] {taskinstance.py:430} INFO - ::endgroup::
[2024-09-21T09:18:31.784+0000] {subprocess.py:63} INFO - Tmp dir root location: /tmp
[2024-09-21T09:18:31.785+0000] {subprocess.py:75} INFO - Running command: ['/bin/bash', '-c', 'dbt run --profiles-dir /opt/***/DBT_Project --project-dir /opt/***/dbt_trip --models STG_dim_Location']
[2024-09-21T09:18:31.803+0000] {subprocess.py:86} INFO - Output:
[2024-09-21T09:18:35.999+0000] {subprocess.py:93} INFO - [0m09:18:35  Running with dbt=1.8.6
[2024-09-21T09:18:36.747+0000] {subprocess.py:93} INFO - [0m09:18:36  Registered adapter: postgres=1.8.2
[2024-09-21T09:18:37.206+0000] {subprocess.py:93} INFO - [0m09:18:37  Unable to do partial parsing because of a version mismatch
[2024-09-21T09:18:40.762+0000] {subprocess.py:93} INFO - [0m09:18:40  [[33mWARNING[0m]: Configuration paths exist in your dbt_project.yml file which do not apply to any resources.
[2024-09-21T09:18:40.762+0000] {subprocess.py:93} INFO - There are 2 unused configuration paths:
[2024-09-21T09:18:40.763+0000] {subprocess.py:93} INFO - - models.fact_trip.core
[2024-09-21T09:18:40.763+0000] {subprocess.py:93} INFO - - models.fact_trip.staging
[2024-09-21T09:18:40.972+0000] {subprocess.py:93} INFO - [0m09:18:40  Found 5 models, 5 seeds, 1 source, 423 macros
[2024-09-21T09:18:40.975+0000] {subprocess.py:93} INFO - [0m09:18:40
[2024-09-21T09:18:41.217+0000] {subprocess.py:93} INFO - [0m09:18:41  Concurrency: 3 threads (target='dev')
[2024-09-21T09:18:41.218+0000] {subprocess.py:93} INFO - [0m09:18:41
[2024-09-21T09:18:41.230+0000] {subprocess.py:93} INFO - [0m09:18:41  1 of 1 START sql view model analysis.STG_dim_Location .......................... [RUN]
[2024-09-21T09:18:41.339+0000] {subprocess.py:93} INFO - [0m09:18:41  1 of 1 ERROR creating sql view model analysis.STG_dim_Location ................. [[31mERROR[0m in 0.11s]
[2024-09-21T09:18:41.358+0000] {subprocess.py:93} INFO - [0m09:18:41
[2024-09-21T09:18:41.359+0000] {subprocess.py:93} INFO - [0m09:18:41  Finished running 1 view model in 0 hours 0 minutes and 0.38 seconds (0.38s).
[2024-09-21T09:18:41.408+0000] {subprocess.py:93} INFO - [0m09:18:41
[2024-09-21T09:18:41.408+0000] {subprocess.py:93} INFO - [0m09:18:41  [31mCompleted with 1 error and 0 warnings:[0m
[2024-09-21T09:18:41.409+0000] {subprocess.py:93} INFO - [0m09:18:41
[2024-09-21T09:18:41.410+0000] {subprocess.py:93} INFO - [0m09:18:41    Database Error in model STG_dim_Location (models/Staging/STG_dim_Location.sql)
[2024-09-21T09:18:41.410+0000] {subprocess.py:93} INFO -   relation "analysis.taxi_zone_lookup" does not exist
[2024-09-21T09:18:41.410+0000] {subprocess.py:93} INFO -   LINE 14:      from "nyc_taxi_trip"."analysis"."taxi_zone_lookup"
[2024-09-21T09:18:41.410+0000] {subprocess.py:93} INFO -                      ^
[2024-09-21T09:18:41.410+0000] {subprocess.py:93} INFO -   compiled Code at target/run/fact_trip/models/Staging/STG_dim_Location.sql
[2024-09-21T09:18:41.411+0000] {subprocess.py:93} INFO - [0m09:18:41
[2024-09-21T09:18:41.411+0000] {subprocess.py:93} INFO - [0m09:18:41  Done. PASS=0 WARN=0 ERROR=1 SKIP=0 TOTAL=1
[2024-09-21T09:18:42.382+0000] {subprocess.py:97} INFO - Command exited with return code 1
[2024-09-21T09:18:42.383+0000] {taskinstance.py:441} INFO - ::group::Post task execution logs
[2024-09-21T09:18:42.393+0000] {taskinstance.py:2905} ERROR - Task failed with exception
Traceback (most recent call last):
  File "/home/airflow/.local/lib/python3.9/site-packages/airflow/models/taskinstance.py", line 465, in _execute_task
    result = _execute_callable(context=context, **execute_callable_kwargs)
  File "/home/airflow/.local/lib/python3.9/site-packages/airflow/models/taskinstance.py", line 432, in _execute_callable
    return execute_callable(context=context, **execute_callable_kwargs)
  File "/home/airflow/.local/lib/python3.9/site-packages/airflow/models/baseoperator.py", line 400, in wrapper
    return func(self, *args, **kwargs)
  File "/home/airflow/.local/lib/python3.9/site-packages/airflow/operators/bash.py", line 243, in execute
    raise AirflowException(
airflow.exceptions.AirflowException: Bash command failed. The command returned a non-zero exit code 1.
[2024-09-21T09:18:42.397+0000] {taskinstance.py:1206} INFO - Marking task as FAILED. dag_id=NYC_Taxi_pipeline, task_id=dbt_models.dbt_Model_STG_dim_Location, run_id=manual__2024-09-21T09:11:40.867116+00:00, execution_date=20240921T091140, start_date=20240921T091831, end_date=20240921T091842
[2024-09-21T09:18:42.410+0000] {standard_task_runner.py:110} ERROR - Failed to execute job 42 for task dbt_models.dbt_Model_STG_dim_Location (Bash command failed. The command returned a non-zero exit code 1.; 356)
[2024-09-21T09:18:42.422+0000] {local_task_job_runner.py:240} INFO - Task exited with return code 1
[2024-09-21T09:18:42.437+0000] {taskinstance.py:3498} INFO - 0 downstream tasks scheduled from follow-on schedule check
[2024-09-21T09:18:42.438+0000] {local_task_job_runner.py:222} INFO - ::endgroup::
