[2024-10-12T09:00:03.600+0000] {local_task_job_runner.py:120} INFO - ::group::Pre task execution logs
[2024-10-12T09:00:03.623+0000] {taskinstance.py:2076} INFO - Dependencies all met for dep_context=non-requeueable deps ti=<TaskInstance: Taxi_trip_pipeline.mark_files_as_processed scheduled__2024-10-12T08:45:00+00:00 [queued]>
[2024-10-12T09:00:03.631+0000] {taskinstance.py:2076} INFO - Dependencies all met for dep_context=requeueable deps ti=<TaskInstance: Taxi_trip_pipeline.mark_files_as_processed scheduled__2024-10-12T08:45:00+00:00 [queued]>
[2024-10-12T09:00:03.632+0000] {taskinstance.py:2306} INFO - Starting attempt 1 of 1
[2024-10-12T09:00:03.643+0000] {taskinstance.py:2330} INFO - Executing <Task(PythonOperator): mark_files_as_processed> on 2024-10-12 08:45:00+00:00
[2024-10-12T09:00:03.651+0000] {standard_task_runner.py:63} INFO - Started process 86 to run task
[2024-10-12T09:00:03.655+0000] {standard_task_runner.py:90} INFO - Running: ['***', 'tasks', 'run', 'Taxi_trip_pipeline', 'mark_files_as_processed', 'scheduled__2024-10-12T08:45:00+00:00', '--job-id', '527', '--raw', '--subdir', 'DAGS_FOLDER/taxi_trip.py', '--cfg-path', '/tmp/tmpggm6p09l']
[2024-10-12T09:00:03.657+0000] {standard_task_runner.py:91} INFO - Job 527: Subtask mark_files_as_processed
[2024-10-12T09:00:03.701+0000] {task_command.py:426} INFO - Running <TaskInstance: Taxi_trip_pipeline.mark_files_as_processed scheduled__2024-10-12T08:45:00+00:00 [running]> on host f02ce4f01a3b
[2024-10-12T09:00:03.790+0000] {taskinstance.py:2648} INFO - Exporting env vars: AIRFLOW_CTX_DAG_OWNER='Mahmoud' AIRFLOW_CTX_DAG_ID='Taxi_trip_pipeline' AIRFLOW_CTX_TASK_ID='mark_files_as_processed' AIRFLOW_CTX_EXECUTION_DATE='2024-10-12T08:45:00+00:00' AIRFLOW_CTX_TRY_NUMBER='1' AIRFLOW_CTX_DAG_RUN_ID='scheduled__2024-10-12T08:45:00+00:00'
[2024-10-12T09:00:03.791+0000] {taskinstance.py:430} INFO - ::endgroup::
[2024-10-12T09:00:03.803+0000] {db_utils.py:19} ERROR - Error while connecting to PostgreSQL: (psycopg2.OperationalError) connection to server at "172.20.0.3", port 5432 failed: Connection refused
	Is the server running on that host and accepting TCP/IP connections?

(Background on this error at: https://sqlalche.me/e/14/e3q8)
[2024-10-12T09:00:03.820+0000] {taxi_trip.py:111} INFO - All files marked as processed successfully.
[2024-10-12T09:00:03.821+0000] {python.py:237} INFO - Done. Returned value was: None
[2024-10-12T09:00:03.821+0000] {taskinstance.py:441} INFO - ::group::Post task execution logs
[2024-10-12T09:00:03.832+0000] {taskinstance.py:1206} INFO - Marking task as SUCCESS. dag_id=Taxi_trip_pipeline, task_id=mark_files_as_processed, run_id=scheduled__2024-10-12T08:45:00+00:00, execution_date=20241012T084500, start_date=20241012T090003, end_date=20241012T090003
[2024-10-12T09:00:03.867+0000] {local_task_job_runner.py:240} INFO - Task exited with return code 0
[2024-10-12T09:00:03.897+0000] {taskinstance.py:3498} INFO - 1 downstream tasks scheduled from follow-on schedule check
[2024-10-12T09:00:03.898+0000] {local_task_job_runner.py:222} INFO - ::endgroup::
